Workbook

Sheet FEES PAYMENT STATUS
B1: FEES PAYMENT SCHEDULE JUNE 2025
A2: STUDENT NO. | B2: NAME | C2: LOCATION | D2: DATE OF ADMISSION | E2: CLASS | F2: BROUGHT FORWARD | G2: STARDARD FEES @PM | H2: ADM FEES | I2: BALANCE | J2: TOTAL PAID | L2: OUTSTANDING | M2: ACCOMODATION | N2: REMARKS
A3: CGHQ 2025/1 | B3: SUSAN NAMUNGOMA | C3: HQ | D3: 45782 | E3: A1 | F3: 10000 | G3: 10000 | H3: 1000 | I3: 10000 | M3: Day
A4: CGHQ 2025/2 | B4: AISHA DADA BARASA | C4: HQ | D4: 45782 | E4: A1 | G4: 15000 | H4: 1000 | I4: 15000 | M4: Hostel
A5: CGHQ 2025/3 | B5: JAMES SIMIYU | C5: HQ | D5: 45782 | E5: A1 | F5: 4000 | G5: 8000 | H5: 1000 | I5: 8000 | M5: Day
A6: CGHQ 2025/4 | B6: AFWAI KARINA PATTLYNN | C6: HQ | D6: 45782 | E6: A1 | G6: 15000 | H6: 1000 | I6: 0 | K6: 15000 | M6: Day
A7: CGHQ 2025/5 | B7: METRINE WANJIKU | C7: HQ | D7: 45782 | E7: A1 | G7: 7500 | H7: 1000 | I7: 7500 | M7: Day
A8: CGHQ 2025/6 | B8: ERIC JUMA | C8: HQ | D8: 45874 | E8: A1 | F8: 1500 | G8: 8000 | H8: 1000 | I8: 8000 | M8: Day
A9: CGHQ 2025/7 | B9: MARION ELISIA NANJALA | C9: HQ | D9: 45996 | E9: A1 | F9: 0 | G9: 7500 | H9: 1000 | I9: 0 | J9: 0 | K9: 0 | L9: 0 | M9: Day | N9: SPONSORED
A10: CGHQ 2025/8 | B10: BLESSINGHOPE ADHIAMBO | C10: HQ | D10: 45996 | E10: A1 | F10: 10000 | G10: 15000 | H10: 0 | I10: 10000 | M10: Day
A11: CGHQ 2025/9 | B11: CINDY SALLY KAHUGANI | C11: HQ | D11: 45996 | E11: A1 | G11: 15000 | H11: 1000 | M11: Day
A12: CGHQ 2025/10 | B12: ABIGAEL WEKESA | C12: HQ | D12: 45996 | E12: A1 | G12: 5000 | H12: 1000 | K12: 15000 | M12: Day
A13: CGHQ 2025/11 | B13: SHIRLEY CHELANG’AT | C13: HQ | D13: 14-05-2025 | E13: A1 | G13: 7500 | H13: 1000 | I13: 1000 | K13: 6500 | M13: Day
A14: CGHQ 2025/12 | B14: FAVOUR MUKOA WAFULA | C14: HQ | D14: 14-5-2025 | E14: A1 | F14: 1500 | G14: 10000 | H14: 0 | I14: 4500 | M14: Day
A15: CGHQ 2025/13 | B15: ZUKI KIBOKI IGNATIUS | C15: HQ | D15: 16-5-2025 | E15: A1 | G15: 7500 | H15: 1000 | K15: 15000 | M15: Day
A16: CGHQ 2025/14 | B16: JOEL KWEMOI JUMA | C16: HQ | D16: 16-5-2025 | E16: A1 | G16: 15000 | H16: 1000 | I16: 15000 | M16: Day
A17: CGHQ 2025/15 | B17: IVENE JEPKURGAT | C17: HQ | D17: 16-5-2025 | E17: A1 | G17: 15000 | H17: 1000 | I17: 15000 | M17: Hostel
A18: CGHQ 2025/16 | B18: VIOLA CHEPCHI | C18: HQ | D18: 16-5-2025 | E18: A1 | G18: 15000 | H18: 1000 | I18: 15000 | M18: Hostel
A19: CGHQ 2025/17 | B19: ZAKAYO MWANJA | C19: HQ | D19: 16-5-2025 | E19: A1 | G19: 15000 | H19: 1000 | I19: 15000 | M19: Hostel
A20: CGHQ 2025/18 | B20: DAVID BLESSED | C20: HQ | D20: 19-5-2025 | E20: A1 | G20: 7500 | H20: 0 | I20: 7500 | M20: Day
A21: CGHQ 2025/19 | B21: DOUGLAS NGECHU THUO | C21: HQ | D21: 20-5-2025 | E21: A1 | G21: 15000 | H21: 1000 | I21: 15000 | M21: Hostel
A22: CGHQ 2025/20 | B22: RICHARD OJUJU | C22: HQ | D22: 45782 | E22: A1 | G22: 7500 | H22: 0 | I22: 2500 | K22: 5000 | M22: Day
A23: CGHQ 2025/21 | B23: EBBY CHEROP | C23: HQ | D23: 45782 | E23: A1 | G23: 7500 | H23: 1000 | I23: 0 | K23: 7500 | M23: Day
A24: CGHQ 2025/22 | B24: STEPHEN BARASA | C24: HQ | D24: 26/5/2025 | E24: A1 | G24: 15000 | H24: 0 | I24: 15000 | M24: Day
A25: CGHQ 2025/23 | B25: JOSEPHAT KOSGEI KAGO | C25: HQ | D25: 26/5/2025 | E25: A1 | G25: 7500 | H25: 0 | I25: 7500 | M25: Day
A26: CGHQ 2025/24 | B26: PRINCE KIBET | C26: HQ | D26: 26/5/2025 | E26: A1 | G26: 15000 | H26: 0 | I26: 15000 | M26: Day
A27: CGHQ 2025/25 | B27: MEAVE CHEPKEMOI NDIEMA | C27: HQ | D27: 27/5/2025 | E27: A1 | G27: 15000 | H27: 0 | I27: 15000 | M27: Day
A28: CGHQ 2025/26 | B28: CONRAD LUSAMULA | C28: HQ | D28: 45722 | E28: A1 | G28: 15000 | H28: 1000 | I28: 5000 | M28: Day
A29: CGHQ 2025/27 | B29: HEZRON MACHARIA | C29: HQ | D29: 45722 | E29: A1 | G29: 7500 | H29: 1000 | I29: 6500 | J29: 1000 | M29: Day
A30: CGKNP 2025/28 | B30: GEORGE BUTIKI | C30: KNP | D30: 17/06/2025 | E30: A1 | G30: 6000 | M30: DAY
A31: CGKNP 2025/29 | B31: ALEX KOOME | C31: KNP | D31: 17/06/2025 | E31: A1 | G31: 5000 | M31: DAY
A32: CGKNP 2025/30 | B32: NOAH KHAEMBA 0NYANDO | C32: KNP | D32: 17/06/2025 | E32: A1 | G32: 5000 | M32: DAY
A33: CGKNP 2025/31 | B33: JOHN MAMATI | C33: KNP | D33: 17/06/2025 | E33: A1 | G33: 5000 | M33: DAY
A34: CGKNP 2025/32 | B34: PETER MURAMBI | C34: KNP | D34: 17/06/2025 | E34: A1 | G34: 5000 | M34: DAY
A35: CGKNP 2025/33 | B35: SHANE MOKEIRA | C35: KNP | D35: 17/06/2025 | E35: A1 | G35: 6000 | M35: DAY
A36: CGKNP 2025/34 | B36: MARION CHEPKWEMOI | C36: KNP | D36: 20/06/2025 | E36: A1 | G36: 5000 | M36: DAY
A37: CGKNP 2025/35 | B37: COLLINES OCHOLA | C37: KNP | D37: 20/06/2025 | E37: A1 | G37: 5000 | M37: DAY
A38: CGKNP 2025/36 | B38: ISMAIL HASSAN | C38: KNP | D38: 20/06/2025 | E38: A1 | G38: 5000 | M38: DAY
A39: CGKNP 2025/37 | B39: SHEDRICK OCHIENG | C39: KNP | D39: 20/06/2025 | E39: A1 | G39: 5000 | M39: DAY
A40: CGKNP 2025/38 | B40: CHEPHUS KIMIBI | C40: KNP | D40: 23/06/2025 | E40: A1 | G40: 5000 | M40: DAY
...

Sheet FULL STUDENT LIST
A1: OLD STUDENT NO. | B1: NEW STUDENT NO | C1: NAME | D1: PHONE | E1: PROFFESSION | F1: REGION | G1: LOCATION | H1: DATE OF ADMISSION | I1: CLASS | J1: DATE OF EXIT | K1: REMARKS | L1: MAY | M1: JUN | N1: JUL | O1: AUG | P1: SEP | Q1: OCT | R1: NOV | S1: DEC | T1: JAN | U1: 4 | V1: MAR | W1: APR | X1: MAY | Y1: JUN | Z1: JUL | AA1: AUG | AB1: SEP | AC1: OCT | AD1: NOV | AE1: DEC | AF1: REMARKS
A2: CGHQ 2025/1 | B2: HDTI/001 | C2: SUSAN NAMUNGOMA | D2: 0116 469984 | E2: FORM 4 LEAVER | F2: HQ | G2: AMBWERE | H2: 45782 | I2: B1 | J2: 45941 | K2: DROPPED | L2: 1000
A3: CGHQ 2025/2 | B3: HDTI/002 | C3: AISHA DADA BARASA | D3: 0740 895206 | E3: HOSPITALITY MANAGEMENT | F3: HQ | G3: AMBWERE | H3: 45782 | I3: B2 | J3: 31/3/2026 | K3: COMPLETED | L3: 21000 | M3: 30000 | T3: 30000 | AF3: CLEAREAD
A4: CGHQ 2025/3 | B4: HDTI/003 | C4: JAMES SIMIYU | D4: 0713 188338 | E4: FORM 4 LEAVER | F4: HQ | G4: AMBWERE | H4: 5/5/202+K45 | I4: A2 | J4: 46093 | K4: DROPPED | L4: 1000 | AF4: DUE TO FEE
A5: CGHQ 2025/4 | B5: HDTI/004 | C5: AFWAI KARINA PATTLYNN | D5: 0727 059662 | E5: FORM 4 LEAVER | F5: HQ | G5: AMBWERE | H5: 45782 | I5: A1 | J5: 45878 | K5: DROPPED | L5: 61000 | AF5: JOINED UNIVERSITY
A6: CGHQ 2025/5 | B6: HDTI/005 | C6: METRINE WANJIKU | D6: 0746 251964 | E6: CERTIFICATE IN COSTOMETOLOGY | F6: HQ | G6: AMBWERE | H6: 45782 | I6: B1 | J6: 46002 | K6: DROPPED | L6: 5250
A7: CGHQ 2025/6 | B7: HDTI/006 | C7: ERIC JUMA | D7: 0707 617507 | E7: FORM 4 LEAVER | F7: HQ | G7: KNP | H7: 45874 | I7: A2 | J7: 46000 | K7: DROPPED | AF7: DUE TO FEE
A8: CGHQ 2025/7 | B8: HDTI/007 | C8: MARION ELISIA NANJALA | D8: 0759 144443 | E8: FORM 4 LEAVER | F8: HQ | G8: AMBWERE | H8: 46361 | I8: B1 | J8: 31/3/2026 | K8: COMPLETED
A9: CGHQ 2025/8 | B9: HDTI/008 | C9: BLESSING HOPE ADHIAMBO | D9: 0705 637032 | E9: UNIVERSITY STUDENT | F9: HQ | G9: AMBWERE | H9: 46361 | I9: B2 | J9: 45786 | K9: DROPPED | L9: 1000 | AF9: JOINED UNIVERSITY
A10: CGHQ 2025/9 | B10: HDTI/009 | C10: CINDY SALLY KAHUGANI | D10: 0722 699502/0116657090 | E10: FORM 4 LEAVER | F10: HQ | G10: AMBWERE | H10: 46361 | J10: 31/3/2026 | K10: COMPLETED | L10: 25000 | Q10: 31000
A11: CGHQ 2025/10 | B11: HDTI/010 | C11: ABIGAEL PEACE WEKESA | D11: 0112 770850/0702805578 | E11: FORM 4 LEAVER | F11: HQ | G11: CAPACITY | H11: 14/5/2025 | I11: B1 | J11: 45809 | K11: DROPPED | AF11: ILLNESS
A12: CGHQ 2025/14 | B12: HDTI/011 | C12: JOEL KWEMOI JUMA | D12: 0727 314736 | E12: FORM 4 LEAVER | F12: HQ | G12: AMBWERE | H12: 14-5-2025 | I12: B2 | J12: 45820 | K12: DROPPED | AF12: WENT WITH JOE
A13: CGHQ 2025/15 | B13: HDTI/012 | C13: IVENE JEPKURGAT | D13: 0793 829236 | E13: FORM 4 LEAVER | F13: HQ | G13: AMBWERE | H13: 16-5-2025 | I13: A1 | J13: 45723 | K13: DROPPED | AF13: JOINED UNIVERSITY
A14: CGHQ 2025/16 | B14: HDTI/013 | C14: VIOLA CHEPCHI | D14: 0115 990331 | E14: FORM 4 LEAVER | F14: HQ | G14: AMBWERE | H14: 16-5-2025 | I14: B2 | J14: 6/12 /21025 | K14: DROPPED | AF14: WENT WITH JOE
A15: CGHQ 2025/17 | B15: HDTI/014 | C15: ZAKAYO MWANJA | D15: 0114B289435 | E15: FORM 4 LEAVER | F15: HQ | G15: AMBWERE | H15: 16-5-2025 | I15: A2 | J15: 45846 | K15: DROPPED | AF15: JOINED UNIVERSITY
A16: CGHQ 2025/18 | B16: HDTI/015 | C16: DAVID BLESSED | D16: 0784 618675 | E16: FORM 4 LEAVER | F16: HQ | G16: AMBWERE | H16: 16-5-2025 | I16: B2 | J16: 31/3/2026 | K16: COMPLETED | L16: 1000 | P16: 5000
A17: CGHQ 2025/19 | B17: HDTI/016 | C17: DOUGLAS NGECHU THUO | D17: 0791 308711 | E17: FORM 4 LEAVER | F17: HQ | G17: AMBWERE | H17: 19-5-2025 | I17: B2 | J17: 46211 | K17: DROPPED | AF17: RELOCATED
A18: CGHQ 2025/20 | B18: HDTI/017 | C18: RICHARD OJUJU | D18: 0719 342465 | E18: COMPUTER SCIENCE | F18: HQ | G18: AMBWERE | H18: 45722 | I18: A1 | J18: 45664 | K18: DROPPED | L18: 5000
A19: CGHQ 2025/21 | B19: HDTI/018 | C19: EBBY CHEROP | D19: 0740 549370 | E19: NURSE | F19: HQ | G19: AMBWERE | H19: 45722 | I19: A2 | J19: 46029 | K19: DROPPED | L19: 8500
A20: CGHQ 2025/22 | B20: HDTI/019 | C20: STEPHEN BARASA | D20: 0745 272643 | E20: FORM 4 LEAVER | F20: HQ | G20: KNP | H20: 26/5/2025 | I20: A1 | J20: 18/9/2025 | K20: DROPPED | L20: 1000
A21: CGHQ 2025/23 | B21: HDTI/020 | C21: JOSEPHAT KOSGEI KAGO | D21: 0740 232791 | E21: FORM 4 LEAVER | F21: HQ | G21: AMBWERE | H21: 25/5/2025 | I21: A1 | J21: 25/5/2025 | K21: DROPPED
A22: CGHQ 2025/24 | B22: HDTI/021 | C22: PRINCE KIBET | D22: 0716 759185/0757 023878 | E22: FORM 4 LEAVER | F22: HQ | G22: AMBWERE | H22: 20-5-2025 | I22: B2 | J22: 31/3/2026 | K22: COMPLETED | L22: 1000 | P22: 10000 | Q22: 10000 | T22: 10000
A23: CGHQ 2025/25 | B23: HDTI/022 | C23: MEAVE CHEPKEMOI NDIEMA | D23: 0758 582496/0722540997 | E23: FORM 4 LEAVER | F23: HQ | G23: AMBWERE | H23: 26/5/2025 | I23: B1 | K23: ONGOING | U23: 15000 | V23: 22500 | AF23: STILL AT AMBWERE
A24: CGHQ 2025/26 | B24: HDTI/023 | C24: CONRAD LUSAMULA | D24: 0705 606628 | E24: REGISTERED NURSE | F24: HQ | G24: AMBWERE | H24: 45722 | I24: A2 | K24: DROPPED | L24: 1000 | R24: 10000
A25: CGHQ 2025/27 | B25: HDTI/024 | C25: HEZRON MACHARIA | D25: 0793 624532 | E25: REGISRERED NURSE | F25: HQ | G25: AMBWERE | H25: 45753 | I25: B1 | K25: DROPPED
A26: CGKNP 2025/28 | B26: HDTI/025 | C26: GEORGE BUTIKI | D26: 0718 922112 | E26: GYM INSRUCTOR AT KNP | F26: HQ | G26: KNP | H26: 17/06/2025 | I26: A1 | J26: 45723 | K26: DROPPED
A27: CGKNP 2025/29 | B27: HDTI/026 | C27: ALEX KOOME | D27: 0115 562825 | F27: HQ | G27: KNP | H27: 17/11/2025 | I27: A1 | J27: 28/18/2025 | K27: DROPPED
A28: CGKNP 2025/30 | B28: HDTI/027 | C28: NOAH KHAEMBA 0NYANDO | D28: 0793 622176 | F28: HQ | G28: KNP | H28: 17/06/2025 | I28: A1 | J28: 22/8/2025 | K28: DROPPED
A29: CGKNP 2025/31 | B29: HDTI/028 | C29: JOHN MAMATI | D29: 0717 873950 | F29: HQ | G29: KNP | H29: 20/06/2025 | I29: A2 | J29: 45845 | K29: DROPPED
A30: CGKNP 2025/32 | B30: HDTI/029 | C30: PETER MURAMBI | D30: 0713 638886 | E30: CYBER SECURITY | F30: HQ | G30: KNP | H30: 20/06/2025 | I30: A1 | J30: 30/6/2025 | K30: DROPPED
A31: CGKNP 2025/33 | B31: HDTI/030 | C31: SHANE MOKEIRA | D31: 0796 540224 | E31: FORM 4 LEAVER | F31: HQ | G31: KNP | H31: 20/06/2025 | I31: A2 | J31: 29/8/2025 | K31: DROPPED | M31: 6000 | AF31: JOINED UNIVERSITY
A32: CGKNP 2025/34 | B32: HDTI/031 | C32: COLLINNIS OCHOLA | D32: 0797 3171403 | E32: ELECTRICAL ENGINNER STUDENT | F32: HQ | G32: KNP | H32: 23/06/2025 | I32: A | J32: 14/6'2025 | K32: DROPPED
A33: CGKNP 2025/35 | B33: HDTI/032 | C33: ISMAIL HASSAN | D33: 0745 550603 | E33: PLUMPING | F33: HQ | G33: KNP | H33: 23/06/2025 | I33: A1 | J33: 23/6/205 | K33: DROPPED
A34: CGKNP 2025/36 | B34: HDTI/033 | C34: SHEDRICK OCHIENG | E34: HOSPITALITY MANAGEMENT | F34: HQ | G34: KNP | H34: 23/06/2025 | I34: A1 | J34: 30/6/2025 | K34: DROPPED
A35: CGKNP 2025/37 | B35: HDTI/034 | C35: CHEPHUS KIMIBI | D35: 0702 942429 | E35: APPLIED SCIENCE&BIOLOGY | F35: HQ | G35: KNP | H35: 23/06/2025 | I35: A1 | J35: 30/062025 | K35: DROPPED
A36: CGKNP 2025/38 | B36: HDTI/035 | C36: LAVIN CYNTHIA EMOTOM | D36: 0746 646196 | E36: HOSPITALITY MANAGEMENT | F36: HQ | G36: KNP | H36: 23/06/2025 | I36: A1 | J36: 45847 | K36: DROPPED
A37: CGKNP 2025/39 | B37: HDTI/036 | C37: NOAH KHAEMBA OYANDO | F37: HQ | G37: KNP | H37: 25/6/2025 | I37: A1 | J37: 28/7/2025 | K37: DROPPED
A38: CGKNP 2025/40 | B38: HDTI/037 | C38: DYLAN SIMIYU JUMA | F38: HQ | G38: AMBWERE | H38: 27/5/2025 | I38: B1 | K38: ONGOING | X38: 5000
A39: CGHQ 2026/01 | B39: HDTI/038 | C39: SHIRLEY CHELANGAT TUMWET | D39: 0700 555780/072321 | E39: FORM 4 LEAVER | F39: HQ | G39: AMBWERE | H39: 45996 | I39: B2 | J39: 31/3/2026 | K39: COMPLETED | L39: 16000 | O39: 16000
A40: CGTC/25/05/002 | B40: HDTI/039 | C40: FAVOUR MUKOA WAFULA | D40: 0722 124008 | E40: FORM 4 LEAVER | F40: HQ | G40: AMBWERE | H40: 14-05-2025 | I40: B2 | K40: COMPLETED
...

Sheet ONLINE
B1: NAME | D1: LEVEL | E1: CAMPUS | F1: PROFFESION | G1: REGISTRATION FEE | H1: TOTAL LEVEL FEE | I1: TOTAL AMNT PAID | J1: BALANCE
B2: DYLAN SIMIYU JUMA | D2: A1 | E2: 0NLINE WEBUYE | F2: NURSE | G2: 1000 | H2: 10000 | I2: 5000 | J2: =H2-I2 -> 5000
B3: TRACY CHEPNGETICH | D3: A2 | E3: ONLINE/KNP | F3: STUDENT | G3: 1000 | H3: 30000 | I3: 8000 | J3: =H3-I3 -> 22000
B4: ELIZABETH SALANO | D4: A1 | E4: ONLINE | F4: NURSE | G4: 1000 | H4: 10000 | I4: 5000 | J4: =H4-I4 -> 5000
B5: SUDANESE GROUP | D5: A2 | E5: ONLINE | F5: 4 STUDENTS | G5: 0 | H5: 40000 | I5: 42550 | J5: =H5-I5 -> -2550
B6: MITCHEL NJERI | D6: A1 | E6: ONLINE/BUNGOMA | F6: NURSE | G6: 0 | H6: 10000 | I6: 0 | J6: =H6-I6 -> 10000
B7: BELINDA LUTUKAYI | D7: A1 | E7: ONLINE/BUNGOMA | F7: NURSE | G7: 0 | H7: 10000 | I7: 0 | J7: =H7-I7 -> 10000
B8: JONH NYONGESA | D8: A1 | E8: ONLINE | F8: STUDENT | G8: 1000 | H8: 10000 | I8: 4000 | J8: =H8-I8 -> 6000
B9: CHRISTINE ABUNGU MPAKA | D9: A1 | E9: ONLINE | F9: STUDENT | G9: 1000 | H9: 10000 | I9: 5000 | J9: =H9-I9 -> 5000
B10: PURITY MONG'ARE KERUBO | D10: A1 | E10: ONLINE | F10: NURSE | G10: 1000 | H10: 10000 | I10: 30000 | J10: =H10-I10 -> -20000
B11: NELLY KENDI | D11: A1 | E11: ONLINE | F11: NURSE | G11: 1000 | H11: 10000 | I11: 5000 | J11: =H11-I11 -> 5000
B12: STEPHEN BRANCO | D12: A1 | E12: ONLINE | F12: NURSE | G12: 1000 | H12: 10000 | I12: 10000 | J12: =H12-I12 -> 0
B13: BRIAN CHANGALWA | D13: A1 | E13: ONLINE | F13: NURSE | G13: 1000 | H13: 10000 | I13: 5000 | J13: 10000
B14: JAMES LUGANU | D14: B2 | E14: ONLINE | F14: MEDIC | G14: 1000 | H14: 22500 | I14: 5000 | J14: =H14-I14 -> 17500
B15: RUTH KAMWASIR | D15: A2 | E15: ONLINE | F15: RADIOGRAPHER | G15: 1000 | H15: 10000 | I15: 2500 | J15: =H15-I15 -> 7500
B16: NASIB ABDALA | D16: A1 | E16: ONLINE | F16: NURSE | G16: 1000 | H16: 10000 | I16: 5000 | J16: =H16-I16 -> 5000
F17: Totals | G17: =SUM(G2:G16) -> 12000 | H17: =SUM(H2:H16) -> 212500 | I17: =SUM(I2:I16) -> 132050 | J17: =SUM(J2:J16) -> 85450
